Workbook
Name AssetName: 'Control Panel'!$B$6
Name RunDate: 'Control Panel'!$B$7
Name AcquisitionDate: 'Control Panel'!$B$8
Name DispositionDate: 'Control Panel'!$B$9
Name HoldMonths: 'Control Panel'!$B$10
Name HoldYears: 'Control Panel'!$B$11
Name BusinessPlanMode: 'Control Panel'!$B$14
Name PriceMode: 'Control Panel'!$B$15
Name TargetReturnBasis: 'Control Panel'!$B$16
Name TargetReturnValue: 'Control Panel'!$B$17
Name RefiOn: 'Control Panel'!$B$18
Name DebtStructure: 'Control Panel'!$B$19
Name Use_LTV: 'Control Panel'!$B$20
Name Use_LTC: 'Control Panel'!$B$21
Name Use_DSCR: 'Control Panel'!$B$22
Name Use_DY: 'Control Panel'!$B$23
Name LoanRateType: 'Control Panel'!$B$24
Name RetailLeaseStructure: 'Control Panel'!$B$25
Name RecoveryMethod: 'Control Panel'!$B$26
Name AdminFeeOn: 'Control Panel'!$B$27
Name GrossUpOn: 'Control Panel'!$B$28
Name ExitValMethod: 'Control Panel'!$B$29
Name ExitNOIBasis: 'Control Panel'!$B$30
Name TaxMethod: 'Control Panel'!$B$31
Name AcqFeeOn: 'Control Panel'!$B$32
Name AMFeeOn: 'Control Panel'!$B$33
Name AMFeeBasis: 'Control Panel'!$B$34
Name DispFeeOn: 'Control Panel'!$B$35
Name GPCatchUpOn: 'Control Panel'!$B$36
Name LP_Present: 'Control Panel'!$B$37
Name Fund_Repairs: 'Control Panel'!$B$40
Name Fund_Reno: 'Control Panel'!$B$41
Name Fund_TILC: 'Control Panel'!$B$42
Name Fund_Contingency: 'Control Panel'!$B$43
Name ModelStatus: 'Control Panel'!$B$46
Name InputPrice: Assumptions!$B$6
Name SolvedPrice: Assumptions!$B$7
Name PurchasePrice: Assumptions!$B$8
Name ClosingCostPct: Assumptions!$B$9
Name DispCostPct: Assumptions!$B$10
Name ExitCapBlended: Assumptions!$B$13
Name ExitCapMF: Assumptions!$B$14
Name ExitCapRetail: Assumptions!$B$15
Name MF_Vacancy: Assumptions!$B$18
Name MF_Concessions: Assumptions!$B$19
Name MF_BadDebt: Assumptions!$B$20
Name LTL_Months: Assumptions!$B$21
Name RenoPremium: Assumptions!$B$24
Name RenoPace: Assumptions!$B$25
Name RenoCostUnit: Assumptions!$B$26
Name RenoDowntime: Assumptions!$B$27
Name LeaseUpStartOcc: Assumptions!$B$28
Name StabilizedOcc: Assumptions!$B$29
Name LeaseUpAbsorption: Assumptions!$B$30
Name RetailGenVacancy: Assumptions!$B$33
Name RetailCreditLoss: Assumptions!$B$34
Name RetailRenewalProb: Assumptions!$B$35
Name RetailDowntime: Assumptions!$B$36
Name RenewalRentFactor: Assumptions!$B$37
Name NewLeaseTI: Assumptions!$B$38

Sheet Control Panel
A1: CONTROL PANEL — Master Toggles
A2: Asset: | B2: =AssetName | D2: Run date: | E2: =RunDate | G2: Business plan: | H2: =BusinessPlanMode | J2: Hold (mo): | K2: =HoldMonths
A3: Model status: | B3: =ModelStatus
A5: Header / identity
A6: Asset Name | B6: Maplewood Commons
A7: Run Date | B7: 46189
A8: Acquisition Date | B8: 46204
A9: Disposition Date | B9: 48030
A10: Hold (months) | B10: =(YEAR(DispositionDate)-YEAR(AcquisitionDate))*12+MONTH(DispositionDate)-MONTH(AcquisitionDate)
A11: Hold (years) | B11: =HoldMonths/12
A13: Master toggles (referenced by name everywhere)
A14: 1. Business Plan Mode | B14: Value-Add | C14: Stabilized | Value-Add | Core-Plus Lease-Up
A15: 3. Price Mode | B15: Input Price | C15: Input Price | Solve for Target Return
A16: 4. Target Return Basis | B16: Levered IRR | C16: Levered IRR | Unlevered IRR | Untrended YoC
A17: 4b. Target Return Value | B17: 0.15 | C17: target metric value (e.g. 0.15 = 15% IRR)
A18: 5. Refi | B18: Off | C18: On | Off
A19: 6. Debt Structure | B19: Single Blended Loan | C19: Single Blended Loan | Separate MF + Retail Loans
A20: 7a. Sizing: LTV constraint | B20: On | C20: On | Off
A21: 7b. Sizing: LTC constraint | B21: On | C21: On | Off
A22: 7c. Sizing: DSCR constraint | B22: On | C22: On | Off
A23: 7d. Sizing: Debt Yield constraint | B23: On | C23: On | Off
A24: 8. Loan Rate Type | B24: Fixed | C24: Fixed | Floating (SOFR + spread)
A25: 9. Retail Lease Structure (global) | B25: NNN | C25: NNN | Gross | Modified Gross
A26: 10. Recovery Method | B26: Pro-rata | C26: Pro-rata
A27: 10a. Admin Fee | B27: On | C27: On | Off
A28: 10b. Gross-Up | B28: On | C28: On | Off
A29: 11. Exit Valuation Method | B29: Blended Cap on Total NOI | C29: Blended Cap on Total NOI | Component Caps
... A37: 17. LP Present | B37: Yes | C37: Yes | No
A39: Capital budget funding (per bucket): Equity | Financed
A40: 14a. Immediate/Deferred Repairs funding | B40: Financed | C40: Equity | Financed
A41: 14b. Value-Add Unit Renovation funding | B41: Financed | C41: Equity | Financed
A42: 14c. Retail TI/LC reserve funding | B42: Financed | C42: Equity | Financed
A43: 14d. Contingency funding | B43: Equity | C43: Equity | Financed
A45: Model status (red on any failed check)
A46: Model Status | B46: =IF(Summary!$B$3=TRUE,"OK","CHECK FAILED")

Sheet Summary
A1: SUMMARY / RETURNS
A2: Asset: | B2: =AssetName | D2: Run date: | E2: =RunDate | G2: Business plan: | H2: =BusinessPlanMode | J2: Hold (mo): | K2: =HoldMonths
A3: All-checks-pass flag | B3: =AND(ABS(SourcesTotal-UsesTotal)<1,ABS(WF_Check-TotalLeveredCF)<MAX(1,ABS(TotalLeveredCF))*0.001,LoanAmount>=0)
A5: Deal snapshot
A6: Purchase price ($) | B6: =PurchasePrice
A7: $/unit | B7: =PurchasePrice/MF_UnitCount
A8: $/SF (total) | B8: =PurchasePrice/(MF_TotalSF+Retail_GLA)
A9: MF units | B9: =MF_UnitCount
A10: Retail GLA (SF) | B10: =Retail_GLA
A11: Going-in cap (%) | B11: =GoingInCap
A12: Stabilized cap (%) | B12: =StabCap
A13: Business plan | B13: =BusinessPlanMode
A15: Sources & Uses
A16: USES
A17: Purchase price | B17: =PurchasePrice
A18: Closing / transaction costs | B18: =PurchasePrice*ClosingCostPct
A19: Capital budget | B19: =TotalCapBudget
A20: Financing costs | B20: =FinancingCosts
A21: Total uses | B21: =SUM(B17:B20)
A23: SOURCES
A24: Loan proceeds | B24: =LoanAmount
A25: Equity | B25: =InitialEquity
A26: Total sources | B26: =SUM(B24:B25)
A28: Returns
A29: Unlevered IRR (%) | B29: =XIRR('Monthly CF'!E$25:DT$25,'Monthly CF'!E$6:DT$6)
A30: Levered IRR (%) | B30: =LeveredIRR
A31: Equity multiple (x) | B31: =EquityMultiple
A32: Yield-on-cost (%) | B32: =YieldOnCost
A33: Exit cap (blended) (%) | B33: =ExitCapBlended
A34: Development spread (bps) | B34: =DevSpread
A35: Loan amount ($) | B35: =LoanAmount
A36: Binding constraint | B36: =BindingConstraint
A37: Initial equity ($) | B37: =InitialEquity
A39: Partner returns (waterfall)
A40: LP IRR (%) | B40: =LP_IRR
A41: GP IRR (%) | B41: =GP_IRR
A42: LP equity multiple (x) | B42: =LP_EM
A43: GP promote ($) | B43: =GPPromote
A44: LP distributions ($) | B44: =LPDist
A45: GP distributions ($) | B45: =GPDist
...

Sheet Assumptions
A1: ASSUMPTIONS — Global Drivers & Growth Block
A2: Asset: | B2: =AssetName | D2: Run date: | E2: =RunDate | G2: Business plan: | H2: =BusinessPlanMode | J2: Hold (mo): | K2: =HoldMonths
A3: Model status: | B3: =ModelStatus
A5: Pricing & cost
A6: Input Purchase Price ($) | B6: 48000000
A7: Solved Max-Bid Price ($) [Python binary search] | B7: 48000000
A8: Active Purchase Price ($) | B8: =IF(PriceMode="Solve for Target Return",SolvedPrice,InputPrice)
A9: Closing / transaction cost (% of price) | B9: 0.018
A10: Disposition cost (% of sale) | B10: 0.015
A12: Exit assumptions
A13: Exit cap — blended (%) | B13: 0.055
A14: Exit cap — MF component (%) | B14: 0.0525
A15: Exit cap — Retail component (%) | B15: 0.0675
A17: MF operating assumptions
A18: Economic vacancy (% of GPR) | B18: 0.05
A19: Concessions (% of GPR) | B19: 0.01
A20: Bad debt (% of GPR) | B20: 0.005
A21: Loss-to-lease burn-off (months to market) | B21: 12
A23: Value-Add / Core-Plus ramps
A24: Renovation premium ($/unit/mo) | B24: 250
A25: Renovation pace (units/month) | B25: 4
A26: Renovation cost ($/unit) | B26: 18000
A27: Renovation downtime (months/unit) | B27: 1
A28: Lease-up: start occupancy (%) | B28: 0.7
A29: Lease-up: stabilized occupancy (%) | B29: 0.95
A30: Lease-up: absorption (units/month) | B30: 6
A32: Retail assumptions
A33: Retail general vacancy (% of retail income) | B33: 0.05
A34: Retail credit loss / bad debt (%) | B34: 0.01
A35: Retail renewal probability (%) | B35: 0.7
A36: Retail re-let downtime (months) | B36: 6
A37: Renewal rent factor (% of market) | B37: 1
A38: New-lease TI ($/SF) | B38: 50
A39: Renewal TI ($/SF) | B39: 15
A40: Leasing commission (% of lease value) | B40: 0.05
A41: Admin fee (% of recoveries) | B41: 0.15
A43: OpEx
A44: Management fee (% of EGI) | B44: 0.03
A45: Replacement reserves ($/unit/yr) | B45: 300
A47: Taxes
...

Sheet MF Revenue
A1: MF REVENUE — Unit-by-Unit Rent Roll
A2: Asset: | B2: =AssetName | D2: Run date: | E2: =RunDate | G2: Business plan: | H2: =BusinessPlanMode | J2: Hold (mo): | K2: =HoldMonths
A3: Model status: | B3: =ModelStatus
A5: Unit ID | B5: Type | C5: SF | D5: In-place rent ($/mo) | E5: Market rent ($/mo) | F5: Lease expiry (mo idx) | G5: Status
A6: U001 | B6: Studio | C6: 520 | D6: 1452 | E6: 1650 | F6: 1 | G6: Occupied
A7: U002 | B7: 1BR | C7: 720 | D7: 1905 | E7: 2165 | F7: 2 | G7: Occupied
A8: U003 | B8: 1BR | C8: 760 | D8: 2006 | E8: 2280 | F8: 3 | G8: Occupied
A9: U004 | B9: 2BR | C9: 1050 | D9: 2504 | E9: 2845 | F9: 4 | G9: Occupied
A10: U005 | B10: 2BR | C10: 1080 | D10: 2561 | E10: 2910 | F10: 5 | G10: Occupied
A11: U006 | B11: 3BR | C11: 1320 | D11: 3080 | E11: 3500 | F11: 6 | G11: Occupied
A12: U007 | B12: Studio | C12: 520 | D12: 1465 | E12: 1665 | F12: 7 | G12: Occupied
A13: U008 | B13: 1BR | C13: 720 | D13: 1918 | E13: 2180 | F13: 8 | G13: Occupied
A14: U009 | B14: 1BR | C14: 760 | D14: 2020 | E14: 2295 | F14: 9 | G14: Occupied
A15: U010 | B15: 2BR | C15: 1050 | D15: 2517 | E15: 2860 | F15: 10 | G15: Occupied
A16: U011 | B16: 2BR | C16: 1080 | D16: 2508 | E16: 2850 | F16: 11 | G16: Occupied
A17: U012 | B17: 3BR | C17: 1320 | D17: 3093 | E17: 3515 | F17: 12 | G17: Occupied
... A93: U088 | B93: 2BR | C93: 1050 | D93: 2490 | E93: 2830 | F93: 16 | G93: Occupied
A94: TOTALS | C94: =SUM(C6:C93) | D94: =SUM(D6:D93) | E94: =SUM(E6:E93) | H94: =COUNTA(A6:A93) | I94: <- unit count
A95: Loss-to-lease = Market - In-place, burning off over LTL_Months to market.
A97: MONTHLY MF BUILD (-> MF EGI). Cols E.. align to Assumptions period header.
A98: Month index | E98: =Assumptions!E$72 | F98: =Assumptions!F$72 | G98: =Assumptions!G$72 | H98: =Assumptions!H$72 | I98: =Assumptions!I$72 | J98: =Assumptions!J$72 | K98: =Assumptions!K$72 | L98: =Assumptions!L$72 | ... DT98: =Assumptions!DT$72
A99: Occupied units (count) | E99: =IF(Assumptions!E$74=0,0,IF(BusinessPlanMode="Core-Plus Lease-Up",MIN(MF_UnitCount*StabilizedOcc, MF_UnitCount*LeaseUpStartOcc + LeaseUpAbsorption*Assumptions!E$72),MF_UnitCount*StabilizedOcc)) | F99: =IF(Assumptions!F$74=0,0,IF(BusinessPlanMode="Core-Plus Lease-Up",MIN(MF_UnitCount*StabilizedOcc, MF_UnitCount*LeaseUpStartOcc + LeaseUpAbsorption*Assumptions!F$72),MF_UnitCount*StabilizedOcc)) | G99: =IF(Assumptions!G$74=0,0,IF(BusinessPlanMode="Core-Plus Lease-Up",MIN(MF_UnitCount*StabilizedOcc, MF_UnitCount*LeaseUpStartOcc + LeaseUpAbsorption*Assumptions!G$72),MF_UnitCount*StabilizedOcc)) | H99: =IF(Assumptions!H$74=0,0,IF(BusinessPlanMode="Core-Plus Lease-Up",MIN(MF_UnitCount*StabilizedOcc, MF_UnitCount*LeaseUpStartOcc + LeaseUpAbsorption*Assumptions!H$72),MF_UnitCount*StabilizedOcc)) | I99: =IF(Assumptions!I$74=0,0,IF(BusinessPlanMode="Core-Plus Lease-Up",MIN(MF_UnitCount*StabilizedOcc, MF_UnitCount*LeaseUpStartOcc + LeaseUpAbsorption*Assumptions!I$72),MF_UnitCount*StabilizedOcc)) | J99: =IF(Assumptions!J$74=0,0,IF(BusinessPlanMode="Core-Plus Lease-Up",MIN(MF_UnitCount*StabilizedOcc, MF_UnitCount*LeaseUpStartOcc + LeaseUpAbsorption*Assumptions!J$72),MF_UnitCount*StabilizedOcc)) | K99: =IF(Assumptions!K$74=0,0,IF(BusinessPlanMode="Core-Plus Lease-Up",MIN(MF_UnitCount*StabilizedOcc, MF_UnitCount*LeaseUpStartOcc + LeaseUpAbsorption*Assumptions!K$72),MF_UnitCount*StabilizedOcc)) | L99: =IF(Assumptions!L$74=0,0,IF(BusinessPlanMode="Core-Plus Lease-Up",MIN(MF_UnitCount*StabilizedOcc, MF_UnitCount*LeaseUpStartOcc + LeaseUpAbsorption*Assumptions!L$72),MF_UnitCount*StabilizedOcc)) | ... DT99: =IF(Assumptions!DT$74=0,0,IF(BusinessPlanMode="Core-Plus Lease-Up",MIN(MF_UnitCount*StabilizedOcc, MF_UnitCount*LeaseUpStartOcc + LeaseUpAbsorption*Assumptions!DT$72),MF_UnitCount*StabilizedOcc))
A100: Renovated units (cumulative) | E100: =IF(BusinessPlanMode="Value-Add",MIN(MF_UnitCount,MAX(0,RenoPace*(Assumptions!E$72-RenoDowntime)))*Assumptions!E$74,0) | F100: =IF(BusinessPlanMode="Value-Add",MIN(MF_UnitCount,MAX(0,RenoPace*(Assumptions!F$72-RenoDowntime)))*Assumptions!F$74,0) | G100: =IF(BusinessPlanMode="Value-Add",MIN(MF_UnitCount,MAX(0,RenoPace*(Assumptions!G$72-RenoDowntime)))*Assumptions!G$74,0) | H100: =IF(BusinessPlanMode="Value-Add",MIN(MF_UnitCount,MAX(0,RenoPace*(Assumptions!H$72-RenoDowntime)))*Assumptions!H$74,0) | I100: =IF(BusinessPlanMode="Value-Add",MIN(MF_UnitCount,MAX(0,RenoPace*(Assumptions!I$72-RenoDowntime)))*Assumptions!I$74,0) | J100: =IF(BusinessPlanMode="Value-Add",MIN(MF_UnitCount,MAX(0,RenoPace*(Assumptions!J$72-RenoDowntime)))*Assumptions!J$74,0) | K100: =IF(BusinessPlanMode="Value-Add",MIN(MF_UnitCount,MAX(0,RenoPace*(Assumptions!K$72-RenoDowntime)))*Assumptions!K$74,0) | L100: =IF(BusinessPlanMode="Value-Add",MIN(MF_UnitCount,MAX(0,RenoPace*(Assumptions!L$72-RenoDowntime)))*Assumptions!L$74,0) | ... DT100: =IF(BusinessPlanMode="Value-Add",MIN(MF_UnitCount,MAX(0,RenoPace*(Assumptions!DT$72-RenoDowntime)))*Assumptions!DT$74,0)
A101: Total in-place rent ($/mo, roll) | E101: =$D$94 | F101: =$D$94 | G101: =$D$94 | H101: =$D$94 | I101: =$D$94 | J101: =$D$94 | K101: =$D$94 | L101: =$D$94 | ... DT101: =$D$94
A102: Total market rent ($/mo, roll) | E102: =$E$94 | F102: =$E$94 | G102: =$E$94 | H102: =$E$94 | I102: =$E$94 | J102: =$E$94 | K102: =$E$94 | L102: =$E$94 | ... DT102: =$E$94
A103: Gross Potential Rent ($/mo) | E103: =(E$102*INDEX(Cum_MFRent,1,Assumptions!E$77)+E$100*RenoPremium)*Assumptions!E$74 | F103: =(F$102*INDEX(Cum_MFRent,1,Assumptions!F$77)+F$100*RenoPremium)*Assumptions!F$74 | G103: =(G$102*INDEX(Cum_MFRent,1,Assumptions!G$77)+G$100*RenoPremium)*Assumptions!G$74 | H103: =(H$102*INDEX(Cum_MFRent,1,Assumptions!H$77)+H$100*RenoPremium)*Assumptions!H$74 | I103: =(I$102*INDEX(Cum_MFRent,1,Assumptions!I$77)+I$100*RenoPremium)*Assumptions!I$74 | J103: =(J$102*INDEX(Cum_MFRent,1,Assumptions!J$77)+J$100*RenoPremium)*Assumptions!J$74 | K103: =(K$102*INDEX(Cum_MFRent,1,Assumptions!K$77)+K$100*RenoPremium)*Assumptions!K$74 | L103: =(L$102*INDEX(Cum_MFRent,1,Assumptions!L$77)+L$100*RenoPremium)*Assumptions!L$74 | ... DT103: =(DT$102*INDEX(Cum_MFRent,1,Assumptions!DT$77)+DT$100*RenoPremium)*Assumptions!DT$74
A104: Loss-to-lease ($/mo, negative) | E104: =-(E$102-E$101)*MAX(0,1-Assumptions!E$72/LTL_Months)*Assumptions!E$74 | F104: =-(F$102-F$101)*MAX(0,1-Assumptions!F$72/LTL_Months)*Assumptions!F$74 | G104: =-(G$102-G$101)*MAX(0,1-Assumptions!G$72/LTL_Months)*Assumptions!G$74 | H104: =-(H$102-H$101)*MAX(0,1-Assumptions!H$72/LTL_Months)*Assumptions!H$74 | I104: =-(I$102-I$101)*MAX(0,1-Assumptions!I$72/LTL_Months)*Assumptions!I$74 | J104: =-(J$102-J$101)*MAX(0,1-Assumptions!J$72/LTL_Months)*Assumptions!J$74 | K104: =-(K$102-K$101)*MAX(0,1-Assumptions!K$72/LTL_Months)*Assumptions!K$74 | L104: =-(L$102-L$101)*MAX(0,1-Assumptions!L$72/LTL_Months)*Assumptions!L$74 | ... DT104: =-(DT$102-DT$101)*MAX(0,1-Assumptions!DT$72/LTL_Months)*Assumptions!DT$74
A105: Vacancy / concessions / bad debt ($/mo, neg) | E105: =-(E$103*(MF_Vacancy+MF_Concessions+MF_BadDebt)+E$103*(1-(E$99/MF_UnitCount))) | F105: =-(F$103*(MF_Vacancy+MF_Concessions+MF_BadDebt)+F$103*(1-(F$99/MF_UnitCount))) | G105: =-(G$103*(MF_Vacancy+MF_Concessions+MF_BadDebt)+G$103*(1-(G$99/MF_UnitCount))) | H105: =-(H$103*(MF_Vacancy+MF_Concessions+MF_BadDebt)+H$103*(1-(H$99/MF_UnitCount))) | I105: =-(I$103*(MF_Vacancy+MF_Concessions+MF_BadDebt)+I$103*(1-(I$99/MF_UnitCount))) | J105: =-(J$103*(MF_Vacancy+MF_Concessions+MF_BadDebt)+J$103*(1-(J$99/MF_UnitCount))) | K105: =-(K$103*(MF_Vacancy+MF_Concessions+MF_BadDebt)+K$103*(1-(K$99/MF_UnitCount))) | L105: =-(L$103*(MF_Vacancy+MF_Concessions+MF_BadDebt)+L$103*(1-(L$99/MF_UnitCount))) | ... DT105: =-(DT$103*(MF_Vacancy+MF_Concessions+MF_BadDebt)+DT$103*(1-(DT$99/MF_UnitCount)))
A106: Other income — itemized ($/unit/mo)
A107: RUBS / utility reimbursement | B107: 45 | E107: =$B$107*E$99*INDEX(Cum_OtherInc,1,Assumptions!E$77)*Assumptions!E$74 | F107: =$B$107*F$99*INDEX(Cum_OtherInc,1,Assumptions!F$77)*Assumptions!F$74 | G107: =$B$107*G$99*INDEX(Cum_OtherInc,1,Assumptions!G$77)*Assumptions!G$74 | H107: =$B$107*H$99*INDEX(Cum_OtherInc,1,Assumptions!H$77)*Assumptions!H$74 | I107: =$B$107*I$99*INDEX(Cum_OtherInc,1,Assumptions!I$77)*Assumptions!I$74 | J107: =$B$107*J$99*INDEX(Cum_OtherInc,1,Assumptions!J$77)*Assumptions!J$74 | K107: =$B$107*K$99*INDEX(Cum_OtherInc,1,Assumptions!K$77)*Assumptions!K$74 | L107: =$B$107*L$99*INDEX(Cum_OtherInc,1,Assumptions!L$77)*Assumptions!L$74 | ... DT107: =$B$107*DT$99*INDEX(Cum_OtherInc,1,Assumptions!DT$77)*Assumptions!DT$74
A108: Parking | B108: 30 | E108: =$B$108*E$99*INDEX(Cum_OtherInc,1,Assumptions!E$77)*Assumptions!E$74 | F108: =$B$108*F$99*INDEX(Cum_OtherInc,1,Assumptions!F$77)*Assumptions!F$74 | G108: =$B$108*G$99*INDEX(Cum_OtherInc,1,Assumptions!G$77)*Assumptions!G$74 | H108: =$B$108*H$99*INDEX(Cum_OtherInc,1,Assumptions!H$77)*Assumptions!H$74 | I108: =$B$108*I$99*INDEX(Cum_OtherInc,1,Assumptions!I$77)*Assumptions!I$74 | J108: =$B$108*J$99*INDEX(Cum_OtherInc,1,Assumptions!J$77)*Assumptions!J$74 | K108: =$B$108*K$99*INDEX(Cum_OtherInc,1,Assumptions!K$77)*Assumptions!K$74 | L108: =$B$108*L$99*INDEX(Cum_OtherInc,1,Assumptions!L$77)*Assumptions!L$74 | ... DT108: =$B$108*DT$99*INDEX(Cum_OtherInc,1,Assumptions!DT$77)*Assumptions!DT$74
A109: Storage | B109: 12 | E109: =$B$109*E$99*INDEX(Cum_OtherInc,1,Assumptions!E$77)*Assumptions!E$74 | F109: =$B$109*F$99*INDEX(Cum_OtherInc,1,Assumptions!F$77)*Assumptions!F$74 | G109: =$B$109*G$99*INDEX(Cum_OtherInc,1,Assumptions!G$77)*Assumptions!G$74 | H109: =$B$109*H$99*INDEX(Cum_OtherInc,1,Assumptions!H$77)*Assumptions!H$74 | I109: =$B$109*I$99*INDEX(Cum_OtherInc,1,Assumptions!I$77)*Assumptions!I$74 | J109: =$B$109*J$99*INDEX(Cum_OtherInc,1,Assumptions!J$77)*Assumptions!J$74 | K109: =$B$109*K$99*INDEX(Cum_OtherInc,1,Assumptions!K$77)*Assumptions!K$74 | L109: =$B$109*L$99*INDEX(Cum_OtherInc,1,Assumptions!L$77)*Assumptions!L$74 | ... DT109: =$B$109*DT$99*INDEX(Cum_OtherInc,1,Assumptions!DT$77)*Assumptions!DT$74
A110: Pet | B110: 8 | E110: =$B$110*E$99*INDEX(Cum_OtherInc,1,Assumptions!E$77)*Assumptions!E$74 | F110: =$B$110*F$99*INDEX(Cum_OtherInc,1,Assumptions!F$77)*Assumptions!F$74 | G110: =$B$110*G$99*INDEX(Cum_OtherInc,1,Assumptions!G$77)*Assumptions!G$74 | H110: =$B$110*H$99*INDEX(Cum_OtherInc,1,Assumptions!H$77)*Assumptions!H$74 | I110: =$B$110*I$99*INDEX(Cum_OtherInc,1,Assumptions!I$77)*Assumptions!I$74 | J110: =$B$110*J$99*INDEX(Cum_OtherInc,1,Assumptions!J$77)*Assumptions!J$74 | K110: =$B$110*K$99*INDEX(Cum_OtherInc,1,Assumptions!K$77)*Assumptions!K$74 | L110: =$B$110*L$99*INDEX(Cum_OtherInc,1,Assumptions!L$77)*Assumptions!L$74 | ... DT110: =$B$110*DT$99*INDEX(Cum_OtherInc,1,Assumptions!DT$77)*Assumptions!DT$74
A111: Application / admin fees | B111: 5 | E111: =$B$111*E$99*INDEX(Cum_OtherInc,1,Assumptions!E$77)*Assumptions!E$74 | F111: =$B$111*F$99*INDEX(Cum_OtherInc,1,Assumptions!F$77)*Assumptions!F$74 | G111: =$B$111*G$99*INDEX(Cum_OtherInc,1,Assumptions!G$77)*Assumptions!G$74 | H111: =$B$111*H$99*INDEX(Cum_OtherInc,1,Assumptions!H$77)*Assumptions!H$74 | I111: =$B$111*I$99*INDEX(Cum_OtherInc,1,Assumptions!I$77)*Assumptions!I$74 | J111: =$B$111*J$99*INDEX(Cum_OtherInc,1,Assumptions!J$77)*Assumptions!J$74 | K111: =$B$111*K$99*INDEX(Cum_OtherInc,1,Assumptions!K$77)*Assumptions!K$74 | L111: =$B$111*L$99*INDEX(Cum_OtherInc,1,Assumptions!L$77)*Assumptions!L$74 | ... DT111: =$B$111*DT$99*INDEX(Cum_OtherInc,1,Assumptions!DT$77)*Assumptions!DT$74
A112: Other | B112: 6 | E112: =$B$112*E$99*INDEX(Cum_OtherInc,1,Assumptions!E$77)*Assumptions!E$74 | F112: =$B$112*F$99*INDEX(Cum_OtherInc,1,Assumptions!F$77)*Assumptions!F$74 | G112: =$B$112*G$99*INDEX(Cum_OtherInc,1,Assumptions!G$77)*Assumptions!G$74 | H112: =$B$112*H$99*INDEX(Cum_OtherInc,1,Assumptions!H$77)*Assumptions!H$74 | I112: =$B$112*I$99*INDEX(Cum_OtherInc,1,Assumptions!I$77)*Assumptions!I$74 | J112: =$B$112*J$99*INDEX(Cum_OtherInc,1,Assumptions!J$77)*Assumptions!J$74 | K112: =$B$112*K$99*INDEX(Cum_OtherInc,1,Assumptions!K$77)*Assumptions!K$74 | L112: =$B$112*L$99*INDEX(Cum_OtherInc,1,Assumptions!L$77)*Assumptions!L$74 | ... DT112: =$B$112*DT$99*INDEX(Cum_OtherInc,1,Assumptions!DT$77)*Assumptions!DT$74
A113: Total other income ($/mo) | E113: =SUM(E107:E112) | F113: =SUM(F107:F112) | G113: =SUM(G107:G112) | H113: =SUM(H107:H112) | I113: =SUM(I107:I112) | J113: =SUM(J107:J112) | K113: =SUM(K107:K112) | L113: =SUM(L107:L112) | ... DT113: =SUM(DT107:DT112)
A114: MF EGI ($/mo) | E114: =E$103+E$104+E$105+E$113 | F114: =F$103+F$104+F$105+F$113 | G114: =G$103+G$104+G$105+G$113 | H114: =H$103+H$104+H$105+H$113 | I114: =I$103+I$104+I$105+I$113 | J114: =J$103+J$104+J$105+J$113 | K114: =K$103+K$104+K$105+K$113 | L114: =L$103+L$104+L$105+L$113 | ... DT114: =DT$103+DT$104+DT$105+DT$113

Sheet Retail Revenue
A1: RETAIL REVENUE — Tenant-by-Tenant
A2: Asset: | B2: =AssetName | D2: Run date: | E2: =RunDate | G2: Business plan: | H2: =BusinessPlanMode | J2: Hold (mo): | K2: =HoldMonths
A3: Model status: | B3: =ModelStatus
A5: Recovery matrix (editable: 1=tenant reimburses, 0=landlord absorbs)
A6: Structure | B6: CAM | C6: Tax | D6: Insurance | E6: Base-year stop?
A7: NNN | B7: 1 | C7: 1 | D7: 1 | E7: 0
A8: Gross | B8: 0 | C8: 0 | D8: 0 | E8: 0
A9: Modified Gross | B9: 1 | C9: 1 | D9: 1 | E9: 1
A11: Recoverable CAM ($/SF/yr) | B11: 6.5
A12: Recoverable Tax ($/SF/yr) | B12: 4
A13: Recoverable Insurance ($/SF/yr) | B13: 1.25
A16: Tenant | B16: Suite SF | C16: Lease start (mo) | D16: Lease expiry (mo) | E16: Base rent ($/SF/yr) | F16: Annual step (%) | G16: Structure (override) | H16: %rent: sales ($/SF/yr) | I16: %rent: overage %
A17: Grocer Anchor | B17: 16000 | C17: 0 | D17: 60 | E17: 30 | F17: 0.02 | G17: NNN | H17: 0 | I17: 0.06
A18: Pharmacy | B18: 9000 | C18: 0 | D18: 84 | E18: 33 | F18: 0.015 | G18: NNN | H18: 0 | I18: 0.05
A19: Cafe | B19: 2400 | C19: 0 | D19: 36 | E19: 46 | F19: 0.03 | G19: NNN | H19: 0 | I19: 0.07
A20: Fitness | B20: 6000 | C20: 0 | D20: 48 | E20: 31 | F20: 0.025 | G20: Modified Gross | H20: 0 | I20: 0.06
A21: Bank | B21: 3200 | C21: 0 | D21: 72 | E21: 40 | F21: 0.02 | G21: NNN | H21: 0 | I21: 0.05
A22: Restaurant | B22: 3600 | C22: 0 | D22: 54 | E22: 42 | F22: 0.025 | G22: NNN | H22: 0 | I22: 0.07
A23: TOTAL GLA | B23: =SUM(B17:B22) | C23: =COUNTA(A17:A22) | I23: Set GLA rows to 0 for pure-MF.
A26: MONTHLY RETAIL BUILD (-> Retail EGI). Per-tenant base rent + steps, then pool lines.
A27: Month index | E27: =Assumptions!E$72 | F27: =Assumptions!F$72 | G27: =Assumptions!G$72 | H27: =Assumptions!H$72 | I27: =Assumptions!I$72 | J27: =Assumptions!J$72 | K27: =Assumptions!K$72 | L27: =Assumptions!L$72 | ... DT27: =Assumptions!DT$72
A28: Per-tenant in-place + rollover base rent ($/mo)
A29: Grocer Anchor | E29: =IF(Assumptions!E$74=0,0,IF(Assumptions!E$72<$C$17,0,IF(Assumptions!E$72<=$D$17,$E$17*$B$17/12*(1+$F$17)^INT((Assumptions!E$72-$C$17)/12),IF(Assumptions!E$72<=$D$17+RetailDowntime,0,1)*$E$17*$B$17/12*INDEX(Cum_RetailRent,1,Assumptions!E$77)*RenewalRentFactor))) | F29: =IF(Assumptions!F$74=0,0,IF(Assumptions!F$72<$C$17,0,IF(Assumptions!F$72<=$D$17,$E$17*$B$17/12*(1+$F$17)^INT((Assumptions!F$72-$C$17)/12),IF(Assumptions!F$72<=$D$17+RetailDowntime,0,1)*$E$17*$B$17/12*INDEX(Cum_RetailRent,1,Assumptions!F$77)*RenewalRentFactor))) | G29: =IF(Assumptions!G$74=0,0,IF(Assumptions!G$72<$C$17,0,IF(Assumptions!G$72<=$D$17,$E$17*$B$17/12*(1+$F$17)^INT((Assumptions!G$72-$C$17)/12),IF(Assumptions!G$72<=$D$17+RetailDowntime,0,1)*$E$17*$B$17/12*INDEX(Cum_RetailRent,1,Assumptions!G$77)*RenewalRentFactor))) | H29: =IF(Assumptions!H$74=0,0,IF(Assumptions!H$72<$C$17,0,IF(Assumptions!H$72<=$D$17,$E$17*$B$17/12*(1+$F$17)^INT((Assumptions!H$72-$C$17)/12),IF(Assumptions!H$72<=$D$17+RetailDowntime,0,1)*$E$17*$B$17/12*INDEX(Cum_RetailRent,1,Assumptions!H$77)*RenewalRentFactor))) | I29: =IF(Assumptions!I$74=0,0,IF(Assumptions!I$72<$C$17,0,IF(Assumptions!I$72<=$D$17,$E$17*$B$17/12*(1+$F$17)^INT((Assumptions!I$72-$C$17)/12),IF(Assumptions!I$72<=$D$17+RetailDowntime,0,1)*$E$17*$B$17/12*INDEX(Cum_RetailRent,1,Assumptions!I$77)*RenewalRentFactor))) | J29: =IF(Assumptions!J$74=0,0,IF(Assumptions!J$72<$C$17,0,IF(Assumptions!J$72<=$D$17,$E$17*$B$17/12*(1+$F$17)^INT((Assumptions!J$72-$C$17)/12),IF(Assumptions!J$72<=$D$17+RetailDowntime,0,1)*$E$17*$B$17/12*INDEX(Cum_RetailRent,1,Assumptions!J$77)*RenewalRentFactor))) | K29: =IF(Assumptions!K$74=0,0,IF(Assumptions!K$72<$C$17,0,IF(Assumptions!K$72<=$D$17,$E$17*$B$17/12*(1+$F$17)^INT((Assumptions!K$72-$C$17)/12),IF(Assumptions!K$72<=$D$17+RetailDowntime,0,1)*$E$17*$B$17/12*INDEX(Cum_RetailRent,1,Assumptions!K$77)*RenewalRentFactor))) | L29: =IF(Assumptions!L$74=0,0,IF(Assumptions!L$72<$C$17,0,IF(Assumptions!L$72<=$D$17,$E$17*$B$17/12*(1+$F$17)^INT((Assumptions!L$72-$C$17)/12),IF(Assumptions!L$72<=$D$17+RetailDowntime,0,1)*$E$17*$B$17/12*INDEX(Cum_RetailRent,1,Assumptions!L$77)*RenewalRentFactor))) | ... DT29: =IF(Assumptions!DT$74=0,0,IF(Assumptions!DT$72<$C$17,0,IF(Assumptions!DT$72<=$D$17,$E$17*$B$17/12*(1+$F$17)^INT((Assumptions!DT$72-$C$17)/12),IF(Assumptions!DT$72<=$D$17+RetailDowntime,0,1)*$E$17*$B$17/12*INDEX(Cum_RetailRent,1,Assumptions!DT$77)*RenewalRentFactor)))
A30: Pharmacy | E30: =IF(Assumptions!E$74=0,0,IF(Assumptions!E$72<$C$18,0,IF(Assumptions!E$72<=$D$18,$E$18*$B$18/12*(1+$F$18)^INT((Assumptions!E$72-$C$18)/12),IF(Assumptions!E$72<=$D$18+RetailDowntime,0,1)*$E$18*$B$18/12*INDEX(Cum_RetailRent,1,Assumptions!E$77)*RenewalRentFactor))) | F30: =IF(Assumptions!F$74=0,0,IF(Assumptions!F$72<$C$18,0,IF(Assumptions!F$72<=$D$18,$E$18*$B$18/12*(1+$F$18)^INT((Assumptions!F$72-$C$18)/12),IF(Assumptions!F$72<=$D$18+RetailDowntime,0,1)*$E$18*$B$18/12*INDEX(Cum_RetailRent,1,Assumptions!F$77)*RenewalRentFactor))) | G30: =IF(Assumptions!G$74=0,0,IF(Assumptions!G$72<$C$18,0,IF(Assumptions!G$72<=$D$18,$E$18*$B$18/12*(1+$F$18)^INT((Assumptions!G$72-$C$18)/12),IF(Assumptions!G$72<=$D$18+RetailDowntime,0,1)*$E$18*$B$18/12*INDEX(Cum_RetailRent,1,Assumptions!G$77)*RenewalRentFactor))) | H30: =IF(Assumptions!H$74=0,0,IF(Assumptions!H$72<$C$18,0,IF(Assumptions!H$72<=$D$18,$E$18*$B$18/12*(1+$F$18)^INT((Assumptions!H$72-$C$18)/12),IF(Assumptions!H$72<=$D$18+RetailDowntime,0,1)*$E$18*$B$18/12*INDEX(Cum_RetailRent,1,Assumptions!H$77)*RenewalRentFactor))) | I30: =IF(Assumptions!I$74=0,0,IF(Assumptions!I$72<$C$18,0,IF(Assumptions!I$72<=$D$18,$E$18*$B$18/12*(1+$F$18)^INT((Assumptions!I$72-$C$18)/12),IF(Assumptions!I$72<=$D$18+RetailDowntime,0,1)*$E$18*$B$18/12*INDEX(Cum_RetailRent,1,Assumptions!I$77)*RenewalRentFactor))) | J30: =IF(Assumptions!J$74=0,0,IF(Assumptions!J$72<$C$18,0,IF(Assumptions!J$72<=$D$18,$E$18*$B$18/12*(1+$F$18)^INT((Assumptions!J$72-$C$18)/12),IF(Assumptions!J$72<=$D$18+RetailDowntime,0,1)*$E$18*$B$18/12*INDEX(Cum_RetailRent,1,Assumptions!J$77)*RenewalRentFactor))) | K30: =IF(Assumptions!K$74=0,0,IF(Assumptions!K$72<$C$18,0,IF(Assumptions!K$72<=$D$18,$E$18*$B$18/12*(1+$F$18)^INT((Assumptions!K$72-$C$18)/12),IF(Assumptions!K$72<=$D$18+RetailDowntime,0,1)*$E$18*$B$18/12*INDEX(Cum_RetailRent,1,Assumptions!K$77)*RenewalRentFactor))) | L30: =IF(Assumptions!L$74=0,0,IF(Assumptions!L$72<$C$18,0,IF(Assumptions!L$72<=$D$18,$E$18*$B$18/12*(1+$F$18)^INT((Assumptions!L$72-$C$18)/12),IF(Assumptions!L$72<=$D$18+RetailDowntime,0,1)*$E$18*$B$18/12*INDEX(Cum_RetailRent,1,Assumptions!L$77)*RenewalRentFactor))) | ... DT30: =IF(Assumptions!DT$74=0,0,IF(Assumptions!DT$72<$C$18,0,IF(Assumptions!DT$72<=$D$18,$E$18*$B$18/12*(1+$F$18)^INT((Assumptions!DT$72-$C$18)/12),IF(Assumptions!DT$72<=$D$18+RetailDowntime,0,1)*$E$18*$B$18/12*INDEX(Cum_RetailRent,1,Assumptions!DT$77)*RenewalRentFactor)))
A31: Cafe | E31: =IF(Assumptions!E$74=0,0,IF(Assumptions!E$72<$C$19,0,IF(Assumptions!E$72<=$D$19,$E$19*$B$19/12*(1+$F$19)^INT((Assumptions!E$72-$C$19)/12),IF(Assumptions!E$72<=$D$19+RetailDowntime,0,1)*$E$19*$B$19/12*INDEX(Cum_RetailRent,1,Assumptions!E$77)*RenewalRentFactor))) | F31: =IF(Assumptions!F$74=0,0,IF(Assumptions!F$72<$C$19,0,IF(Assumptions!F$72<=$D$19,$E$19*$B$19/12*(1+$F$19)^INT((Assumptions!F$72-$C$19)/12),IF(Assumptions!F$72<=$D$19+RetailDowntime,0,1)*$E$19*$B$19/12*INDEX(Cum_RetailRent,1,Assumptions!F$77)*RenewalRentFactor))) | G31: =IF(Assumptions!G$74=0,0,IF(Assumptions!G$72<$C$19,0,IF(Assumptions!G$72<=$D$19,$E$19*$B$19/12*(1+$F$19)^INT((Assumptions!G$72-$C$19)/12),IF(Assumptions!G$72<=$D$19+RetailDowntime,0,1)*$E$19*$B$19/12*INDEX(Cum_RetailRent,1,Assumptions!G$77)*RenewalRentFactor))) | H31: =IF(Assumptions!H$74=0,0,IF(Assumptions!H$72<$C$19,0,IF(Assumptions!H$72<=$D$19,$E$19*$B$19/12*(1+$F$19)^INT((Assumptions!H$72-$C$19)/12),IF(Assumptions!H$72<=$D$19+RetailDowntime,0,1)*$E$19*$B$19/12*INDEX(Cum_RetailRent,1,Assumptions!H$77)*RenewalRentFactor))) | I31: =IF(Assumptions!I$74=0,0,IF(Assumptions!I$72<$C$19,0,IF(Assumptions!I$72<=$D$19,$E$19*$B$19/12*(1+$F$19)^INT((Assumptions!I$72-$C$19)/12),IF(Assumptions!I$72<=$D$19+RetailDowntime,0,1)*$E$19*$B$19/12*INDEX(Cum_RetailRent,1,Assumptions!I$77)*RenewalRentFactor))) | J31: =IF(Assumptions!J$74=0,0,IF(Assumptions!J$72<$C$19,0,IF(Assumptions!J$72<=$D$19,$E$19*$B$19/12*(1+$F$19)^INT((Assumptions!J$72-$C$19)/12),IF(Assumptions!J$72<=$D$19+RetailDowntime,0,1)*$E$19*$B$19/12*INDEX(Cum_RetailRent,1,Assumptions!J$77)*RenewalRentFactor))) | K31: =IF(Assumptions!K$74=0,0,IF(Assumptions!K$72<$C$19,0,IF(Assumptions!K$72<=$D$19,$E$19*$B$19/12*(1+$F$19)^INT((Assumptions!K$72-$C$19)/12),IF(Assumptions!K$72<=$D$19+RetailDowntime,0,1)*$E$19*$B$19/12*INDEX(Cum_RetailRent,1,Assumptions!K$77)*RenewalRentFactor))) | L31: =IF(Assumptions!L$74=0,0,IF(Assumptions!L$72<$C$19,0,IF(Assumptions!L$72<=$D$19,$E$19*$B$19/12*(1+$F$19)^INT((Assumptions!L$72-$C$19)/12),IF(Assumptions!L$72<=$D$19+RetailDowntime,0,1)*$E$19*$B$19/12*INDEX(Cum_RetailRent,1,Assumptions!L$77)*RenewalRentFactor))) | ... DT31: =IF(Assumptions!DT$74=0,0,IF(Assumptions!DT$72<$C$19,0,IF(Assumptions!DT$72<=$D$19,$E$19*$B$19/12*(1+$F$19)^INT((Assumptions!DT$72-$C$19)/12),IF(Assumptions!DT$72<=$D$19+RetailDowntime,0,1)*$E$19*$B$19/12*INDEX(Cum_RetailRent,1,Assumptions!DT$77)*RenewalRentFactor)))
A32: Fitness | E32: =IF(Assumptions!E$74=0,0,IF(Assumptions!E$72<$C$20,0,IF(Assumptions!E$72<=$D$20,$E$20*$B$20/12*(1+$F$20)^INT((Assumptions!E$72-$C$20)/12),IF(Assumptions!E$72<=$D$20+RetailDowntime,0,1)*$E$20*$B$20/12*INDEX(Cum_RetailRent,1,Assumptions!E$77)*RenewalRentFactor))) | F32: =IF(Assumptions!F$74=0,0,IF(Assumptions!F$72<$C$20,0,IF(Assumptions!F$72<=$D$20,$E$20*$B$20/12*(1+$F$20)^INT((Assumptions!F$72-$C$20)/12),IF(Assumptions!F$72<=$D$20+RetailDowntime,0,1)*$E$20*$B$20/12*INDEX(Cum_RetailRent,1,Assumptions!F$77)*RenewalRentFactor))) | G32: =IF(Assumptions!G$74=0,0,IF(Assumptions!G$72<$C$20,0,IF(Assumptions!G$72<=$D$20,$E$20*$B$20/12*(1+$F$20)^INT((Assumptions!G$72-$C$20)/12),IF(Assumptions!G$72<=$D$20+RetailDowntime,0,1)*$E$20*$B$20/12*INDEX(Cum_RetailRent,1,Assumptions!G$77)*RenewalRentFactor))) | H32: =IF(Assumptions!H$74=0,0,IF(Assumptions!H$72<$C$20,0,IF(Assumptions!H$72<=$D$20,$E$20*$B$20/12*(1+$F$20)^INT((Assumptions!H$72-$C$20)/12),IF(Assumptions!H$72<=$D$20+RetailDowntime,0,1)*$E$20*$B$20/12*INDEX(Cum_RetailRent,1,Assumptions!H$77)*RenewalRentFactor))) | I32: =IF(Assumptions!I$74=0,0,IF(Assumptions!I$72<$C$20,0,IF(Assumptions!I$72<=$D$20,$E$20*$B$20/12*(1+$F$20)^INT((Assumptions!I$72-$C$20)/12),IF(Assumptions!I$72<=$D$20+RetailDowntime,0,1)*$E$20*$B$20/12*INDEX(Cum_RetailRent,1,Assumptions!I$77)*RenewalRentFactor))) | J32: =IF(Assumptions!J$74=0,0,IF(Assumptions!J$72<$C$20,0,IF(Assumptions!J$72<=$D$20,$E$20*$B$20/12*(1+$F$20)^INT((Assumptions!J$72-$C$20)/12),IF(Assumptions!J$72<=$D$20+RetailDowntime,0,1)*$E$20*$B$20/12*INDEX(Cum_RetailRent,1,Assumptions!J$77)*RenewalRentFactor))) | K32: =IF(Assumptions!K$74=0,0,IF(Assumptions!K$72<$C$20,0,IF(Assumptions!K$72<=$D$20,$E$20*$B$20/12*(1+$F$20)^INT((Assumptions!K$72-$C$20)/12),IF(Assumptions!K$72<=$D$20+RetailDowntime,0,1)*$E$20*$B$20/12*INDEX(Cum_RetailRent,1,Assumptions!K$77)*RenewalRentFactor))) | L32: =IF(Assumptions!L$74=0,0,IF(Assumptions!L$72<$C$20,0,IF(Assumptions!L$72<=$D$20,$E$20*$B$20/12*(1+$F$20)^INT((Assumptions!L$72-$C$20)/12),IF(Assumptions!L$72<=$D$20+RetailDowntime,0,1)*$E$20*$B$20/12*INDEX(Cum_RetailRent,1,Assumptions!L$77)*RenewalRentFactor))) | ... DT32: =IF(Assumptions!DT$74=0,0,IF(Assumptions!DT$72<$C$20,0,IF(Assumptions!DT$72<=$D$20,$E$20*$B$20/12*(1+$F$20)^INT((Assumptions!DT$72-$C$20)/12),IF(Assumptions!DT$72<=$D$20+RetailDowntime,0,1)*$E$20*$B$20/12*INDEX(Cum_RetailRent,1,Assumptions!DT$77)*RenewalRentFactor)))
A33: Bank | E33: =IF(Assumptions!E$74=0,0,IF(Assumptions!E$72<$C$21,0,IF(Assumptions!E$72<=$D$21,$E$21*$B$21/12*(1+$F$21)^INT((Assumptions!E$72-$C$21)/12),IF(Assumptions!E$72<=$D$21+RetailDowntime,0,1)*$E$21*$B$21/12*INDEX(Cum_RetailRent,1,Assumptions!E$77)*RenewalRentFactor))) | F33: =IF(Assumptions!F$74=0,0,IF(Assumptions!F$72<$C$21,0,IF(Assumptions!F$72<=$D$21,$E$21*$B$21/12*(1+$F$21)^INT((Assumptions!F$72-$C$21)/12),IF(Assumptions!F$72<=$D$21+RetailDowntime,0,1)*$E$21*$B$21/12*INDEX(Cum_RetailRent,1,Assumptions!F$77)*RenewalRentFactor))) | G33: =IF(Assumptions!G$74=0,0,IF(Assumptions!G$72<$C$21,0,IF(Assumptions!G$72<=$D$21,$E$21*$B$21/12*(1+$F$21)^INT((Assumptions!G$72-$C$21)/12),IF(Assumptions!G$72<=$D$21+RetailDowntime,0,1)*$E$21*$B$21/12*INDEX(Cum_RetailRent,1,Assumptions!G$77)*RenewalRentFactor))) | H33: =IF(Assumptions!H$74=0,0,IF(Assumptions!H$72<$C$21,0,IF(Assumptions!H$72<=$D$21,$E$21*$B$21/12*(1+$F$21)^INT((Assumptions!H$72-$C$21)/12),IF(Assumptions!H$72<=$D$21+RetailDowntime,0,1)*$E$21*$B$21/12*INDEX(Cum_RetailRent,1,Assumptions!H$77)*RenewalRentFactor))) | I33: =IF(Assumptions!I$74=0,0,IF(Assumptions!I$72<$C$21,0,IF(Assumptions!I$72<=$D$21,$E$21*$B$21/12*(1+$F$21)^INT((Assumptions!I$72-$C$21)/12),IF(Assumptions!I$72<=$D$21+RetailDowntime,0,1)*$E$21*$B$21/12*INDEX(Cum_RetailRent,1,Assumptions!I$77)*RenewalRentFactor))) | J33: =IF(Assumptions!J$74=0,0,IF(Assumptions!J$72<$C$21,0,IF(Assumptions!J$72<=$D$21,$E$21*$B$21/12*(1+$F$21)^INT((Assumptions!J$72-$C$21)/12),IF(Assumptions!J$72<=$D$21+RetailDowntime,0,1)*$E$21*$B$21/12*INDEX(Cum_RetailRent,1,Assumptions!J$77)*RenewalRentFactor))) | K33: =IF(Assumptions!K$74=0,0,IF(Assumptions!K$72<$C$21,0,IF(Assumptions!K$72<=$D$21,$E$21*$B$21/12*(1+$F$21)^INT((Assumptions!K$72-$C$21)/12),IF(Assumptions!K$72<=$D$21+RetailDowntime,0,1)*$E$21*$B$21/12*INDEX(Cum_RetailRent,1,Assumptions!K$77)*RenewalRentFactor))) | L33: =IF(Assumptions!L$74=0,0,IF(Assumptions!L$72<$C$21,0,IF(Assumptions!L$72<=$D$21,$E$21*$B$21/12*(1+$F$21)^INT((Assumptions!L$72-$C$21)/12),IF(Assumptions!L$72<=$D$21+RetailDowntime,0,1)*$E$21*$B$21/12*INDEX(Cum_RetailRent,1,Assumptions!L$77)*RenewalRentFactor))) | ... DT33: =IF(Assumptions!DT$74=0,0,IF(Assumptions!DT$72<$C$21,0,IF(Assumptions!DT$72<=$D$21,$E$21*$B$21/12*(1+$F$21)^INT((Assumptions!DT$72-$C$21)/12),IF(Assumptions!DT$72<=$D$21+RetailDowntime,0,1)*$E$21*$B$21/12*INDEX(Cum_RetailRent,1,Assumptions!DT$77)*RenewalRentFactor)))
A34: Restaurant | E34: =IF(Assumptions!E$74=0,0,IF(Assumptions!E$72<$C$22,0,IF(Assumptions!E$72<=$D$22,$E$22*$B$22/12*(1+$F$22)^INT((Assumptions!E$72-$C$22)/12),IF(Assumptions!E$72<=$D$22+RetailDowntime,0,1)*$E$22*$B$22/12*INDEX(Cum_RetailRent,1,Assumptions!E$77)*RenewalRentFactor))) | F34: =IF(Assumptions!F$74=0,0,IF(Assumptions!F$72<$C$22,0,IF(Assumptions!F$72<=$D$22,$E$22*$B$22/12*(1+$F$22)^INT((Assumptions!F$72-$C$22)/12),IF(Assumptions!F$72<=$D$22+RetailDowntime,0,1)*$E$22*$B$22/12*INDEX(Cum_RetailRent,1,Assumptions!F$77)*RenewalRentFactor))) | G34: =IF(Assumptions!G$74=0,0,IF(Assumptions!G$72<$C$22,0,IF(Assumptions!G$72<=$D$22,$E$22*$B$22/12*(1+$F$22)^INT((Assumptions!G$72-$C$22)/12),IF(Assumptions!G$72<=$D$22+RetailDowntime,0,1)*$E$22*$B$22/12*INDEX(Cum_RetailRent,1,Assumptions!G$77)*RenewalRentFactor))) | H34: =IF(Assumptions!H$74=0,0,IF(Assumptions!H$72<$C$22,0,IF(Assumptions!H$72<=$D$22,$E$22*$B$22/12*(1+$F$22)^INT((Assumptions!H$72-$C$22)/12),IF(Assumptions!H$72<=$D$22+RetailDowntime,0,1)*$E$22*$B$22/12*INDEX(Cum_RetailRent,1,Assumptions!H$77)*RenewalRentFactor))) | I34: =IF(Assumptions!I$74=0,0,IF(Assumptions!I$72<$C$22,0,IF(Assumptions!I$72<=$D$22,$E$22*$B$22/12*(1+$F$22)^INT((Assumptions!I$72-$C$22)/12),IF(Assumptions!I$72<=$D$22+RetailDowntime,0,1)*$E$22*$B$22/12*INDEX(Cum_RetailRent,1,Assumptions!I$77)*RenewalRentFactor))) | J34: =IF(Assumptions!J$74=0,0,IF(Assumptions!J$72<$C$22,0,IF(Assumptions!J$72<=$D$22,$E$22*$B$22/12*(1+$F$22)^INT((Assumptions!J$72-$C$22)/12),IF(Assumptions!J$72<=$D$22+RetailDowntime,0,1)*$E$22*$B$22/12*INDEX(Cum_RetailRent,1,Assumptions!J$77)*RenewalRentFactor))) | K34: =IF(Assumptions!K$74=0,0,IF(Assumptions!K$72<$C$22,0,IF(Assumptions!K$72<=$D$22,$E$22*$B$22/12*(1+$F$22)^INT((Assumptions!K$72-$C$22)/12),IF(Assumptions!K$72<=$D$22+RetailDowntime,0,1)*$E$22*$B$22/12*INDEX(Cum_RetailRent,1,Assumptions!K$77)*RenewalRentFactor))) | L34: =IF(Assumptions!L$74=0,0,IF(Assumptions!L$72<$C$22,0,IF(Assumptions!L$72<=$D$22,$E$22*$B$22/12*(1+$F$22)^INT((Assumptions!L$72-$C$22)/12),IF(Assumptions!L$72<=$D$22+RetailDowntime,0,1)*$E$22*$B$22/12*INDEX(Cum_RetailRent,1,Assumptions!L$77)*RenewalRentFactor))) | ... DT34: =IF(Assumptions!DT$74=0,0,IF(Assumptions!DT$72<$C$22,0,IF(Assumptions!DT$72<=$D$22,$E$22*$B$22/12*(1+$F$22)^INT((Assumptions!DT$72-$C$22)/12),IF(Assumptions!DT$72<=$D$22+RetailDowntime,0,1)*$E$22*$B$22/12*INDEX(Cum_RetailRent,1,Assumptions!DT$77)*RenewalRentFactor)))
A35: Total base + steps + rollover ($/mo) | E35: =SUM(E29:E34) | F35: =SUM(F29:F34) | G35: =SUM(G29:G34) | H35: =SUM(H29:H34) | I35: =SUM(I29:I34) | J35: =SUM(J29:J34) | K35: =SUM(K29:K34) | L35: =SUM(L29:L34) | ... DT35: =SUM(DT29:DT34)
A36: Percentage rent ($/mo) | E36: =(IF($I$17=0,0,MAX(0,$H$17*$B$17-($E$17*$B$17/$I$17))*$I$17/12)+IF($I$18=0,0,MAX(0,$H$18*$B$18-($E$18*$B$18/$I$18))*$I$18/12)+IF($I$19=0,0,MAX(0,$H$19*$B$19-($E$19*$B$19/$I$19))*$I$19/12)+IF($I$20=0,0,MAX(0,$H$20*$B$20-($E$20*$B$20/$I$20))*$I$20/12)+IF($I$21=0,0,MAX(0,$H$21*$B$21-($E$21*$B$21/$I$21))*$I$21/12)+IF($I$22=0,0,MAX(0,$H$22*$B$22-($E$22*$B$22/$I$22))*$I$22/12))*Assumptions!E$74 | F36: =(IF($I$17=0,0,MAX(0,$H$17*$B$17-($E$17*$B$17/$I$17))*$I$17/12)+IF($I$18=0,0,MAX(0,$H$18*$B$18-($E$18*$B$18/$I$18))*$I$18/12)+IF($I$19=0,0,MAX(0,$H$19*$B$19-($E$19*$B$19/$I$19))*$I$19/12)+IF($I$20=0,0,MAX(0,$H$20*$B$20-($E$20*$B$20/$I$20))*$I$20/12)+IF($I$21=0,0,MAX(0,$H$21*$B$21-($E$21*$B$21/$I$21))*$I$21/12)+IF($I$22=0,0,MAX(0,$H$22*$B$22-($E$22*$B$22/$I$22))*$I$22/12))*Assumptions!F$74 | G36: =(IF($I$17=0,0,MAX(0,$H$17*$B$17-($E$17*$B$17/$I$17))*$I$17/12)+IF($I$18=0,0,MAX(0,$H$18*$B$18-($E$18*$B$18/$I$18))*$I$18/12)+IF($I$19=0,0,MAX(0,$H$19*$B$19-($E$19*$B$19/$I$19))*$I$19/12)+IF($I$20=0,0,MAX(0,$H$20*$B$20-($E$20*$B$20/$I$20))*$I$20/12)+IF($I$21=0,0,MAX(0,$H$21*$B$21-($E$21*$B$21/$I$21))*$I$21/12)+IF($I$22=0,0,MAX(0,$H$22*$B$22-($E$22*$B$22/$I$22))*$I$22/12))*Assumptions!G$74 | H36: =(IF($I$17=0,0,MAX(0,$H$17*$B$17-($E$17*$B$17/$I$17))*$I$17/12)+IF($I$18=0,0,MAX(0,$H$18*$B$18-($E$18*$B$18/$I$18))*$I$18/12)+IF($I$19=0,0,MAX(0,$H$19*$B$19-($E$19*$B$19/$I$19))*$I$19/12)+IF($I$20=0,0,MAX(0,$H$20*$B$20-($E$20*$B$20/$I$20))*$I$20/12)+IF($I$21=0,0,MAX(0,$H$21*$B$21-($E$21*$B$21/$I$21))*$I$21/12)+IF($I$22=0,0,MAX(0,$H$22*$B$22-($E$22*$B$22/$I$22))*$I$22/12))*Assumptions!H$74 | I36: =(IF($I$17=0,0,MAX(0,$H$17*$B$17-($E$17*$B$17/$I$17))*$I$17/12)+IF($I$18=0,0,MAX(0,$H$18*$B$18-($E$18*$B$18/$I$18))*$I$18/12)+IF($I$19=0,0,MAX(0,$H$19*$B$19-($E$19*$B$19/$I$19))*$I$19/12)+IF($I$20=0,0,MAX(0,$H$20*$B$20-($E$20*$B$20/$I$20))*$I$20/12)+IF($I$21=0,0,MAX(0,$H$21*$B$21-($E$21*$B$21/$I$21))*$I$21/12)+IF($I$22=0,0,MAX(0,$H$22*$B$22-($E$22*$B$22/$I$22))*$I$22/12))*Assumptions!I$74 | J36: =(IF($I$17=0,0,MAX(0,$H$17*$B$17-($E$17*$B$17/$I$17))*$I$17/12)+IF($I$18=0,0,MAX(0,$H$18*$B$18-($E$18*$B$18/$I$18))*$I$18/12)+IF($I$19=0,0,MAX(0,$H$19*$B$19-($E$19*$B$19/$I$19))*$I$19/12)+IF($I$20=0,0,MAX(0,$H$20*$B$20-($E$20*$B$20/$I$20))*$I$20/12)+IF($I$21=0,0,MAX(0,$H$21*$B$21-($E$21*$B$21/$I$21))*$I$21/12)+IF($I$22=0,0,MAX(0,$H$22*$B$22-($E$22*$B$22/$I$22))*$I$22/12))*Assumptions!J$74 | K36: =(IF($I$17=0,0,MAX(0,$H$17*$B$17-($E$17*$B$17/$I$17))*$I$17/12)+IF($I$18=0,0,MAX(0,$H$18*$B$18-($E$18*$B$18/$I$18))*$I$18/12)+IF($I$19=0,0,MAX(0,$H$19*$B$19-($E$19*$B$19/$I$19))*$I$19/12)+IF($I$20=0,0,MAX(0,$H$20*$B$20-($E$20*$B$20/$I$20))*$I$20/12)+IF($I$21=0,0,MAX(0,$H$21*$B$21-($E$21*$B$21/$I$21))*$I$21/12)+IF($I$22=0,0,MAX(0,$H$22*$B$22-($E$22*$B$22/$I$22))*$I$22/12))*Assumptions!K$74 | L36: =(IF($I$17=0,0,MAX(0,$H$17*$B$17-($E$17*$B$17/$I$17))*$I$17/12)+IF($I$18=0,0,MAX(0,$H$18*$B$18-($E$18*$B$18/$I$18))*$I$18/12)+IF($I$19=0,0,MAX(0,$H$19*$B$19-($E$19*$B$19/$I$19))*$I$19/12)+IF($I$20=0,0,MAX(0,$H$20*$B$20-($E$20*$B$20/$I$20))*$I$20/12)+IF($I$21=0,0,MAX(0,$H$21*$B$21-($E$21*$B$21/$I$21))*$I$21/12)+IF($I$22=0,0,MAX(0,$H$22*$B$22-($E$22*$B$22/$I$22))*$I$22/12))*Assumptions!L$74 | ... DT36: =(IF($I$17=0,0,MAX(0,$H$17*$B$17-($E$17*$B$17/$I$17))*$I$17/12)+IF($I$18=0,0,MAX(0,$H$18*$B$18-($E$18*$B$18/$I$18))*$I$18/12)+IF($I$19=0,0,MAX(0,$H$19*$B$19-($E$19*$B$19/$I$19))*$I$19/12)+IF($I$20=0,0,MAX(0,$H$20*$B$20-($E$20*$B$20/$I$20))*$I$20/12)+IF($I$21=0,0,MAX(0,$H$21*$B$21-($E$21*$B$21/$I$21))*$I$21/12)+IF($I$22=0,0,MAX(0,$H$22*$B$22-($E$22*$B$22/$I$22))*$I$22/12))*Assumptions!DT$74
